Workbook

Sheet Dashboard
B2: PMG ATACADISTA · RELATÓRIO DE SELL-OUT | AN2: Atualizado em 30/09/2026
B3: =Dados!$AA$2 -> Alibra | AN3: Base: jan/2024 a set/2026
B4: =Calc!$B$121 -> Vendas da PMG para o food service · jan–set 2026, comparado com o mesmo período de 2025 | AN4: Clique nos filtros para mudar o recorte
B6: ANO | H6: ATÉ O MÊS | K6: PRODUTO | V6: SEGMENTO
B7: 2026 | H7: set | K7: Todos | V7: Todos
D10: Faturamento | M10: Volume | W10: Clientes positivados | AK10: Pedidos | AS10: Ticket médio por pedido
D11: =Calc!$B$12 -> 2713238.8 | M11: =Calc!$B$13 -> 126898.36 | W11: =Calc!$B$14 -> 674 | AK11: =Calc!$B$15 -> 4635 | AS11: =Calc!$B$17 -> 585.38054
D12: =Calc!$D$12 -> 0.15268965 | F12: =Calc!$E$12 -> 2353832.9 | M12: =Calc!$D$13 -> 0.17449327 | O12: =Calc!$E$13 -> 108045.2 | W12: =Calc!$D$14 -> 0.12333333 | Z12: =IF(Calc!$E$14="","",IF(Calc!$B$16="","vs "&Calc!$E$14,"vs "&Calc!$E$14&" · "&Calc!$B$16&" novos")) -> vs 600 · 385 novos | AK12: =Calc!$D$15 -> 0.08853922 | AM12: =Calc!$E$15 -> 4258 | AS12: =Calc!$D$17 -> 0.058932585 | AU12: =Calc!$E$17 -> 552.80246
E16: Faturamento mensal, ano contra ano | AI16: Faturamento por segmento
E17: =Calc!$B$33 -> Melhor mês de 2026: set/26 · R$ 391 mil | AI17: =Calc!$B$90 -> Pizzaria responde por 41,5% do faturamento e cresceu 36,1%
AI19: SEGMENTO | AO19: R$ NO PERÍODO | AT19: PART. | AV19: VS ANO ANT.
AI20: =Calc!$B$80 -> Pizzaria | AO20: =Calc!$G$80 -> ██████████████████████ | AT20: =Calc!$E$80 -> 0.41531463 | AV20: =Calc!$F$80 -> 0.36101847
AI21: =Calc!$B$81 -> Restaurante / Cantina | AO21: =Calc!$G$81 -> █████████ | AT21: =Calc!$E$81 -> 0.17746304 | AV21: =Calc!$F$81 -> -0.056723244
AI22: =Calc!$B$82 -> Cozinha Industrial | AO22: =Calc!$G$82 -> ██████ | AT22: =Calc!$E$82 -> 0.11913037 | AV22: =Calc!$F$82 -> 1.5749425
AI23: =Calc!$B$83 -> Fábrica de Massas | AO23: =Calc!$G$83 -> ███ | AT23: =Calc!$E$83 -> 0.051719981 | AV23: =Calc!$F$83 -> -0.47542239
AI24: =Calc!$B$84 -> Pessoa Física | AO24: =Calc!$G$84 -> ██ | AT24: =Calc!$E$84 -> 0.033313337 | AV24: =Calc!$F$84 -> 0.29988469
AI25: =Calc!$B$85 -> Lanchonete / Cafeteria | AO25: =Calc!$G$85 -> ██ | AT25: =Calc!$E$85 -> 0.030828138 | AV25: =Calc!$F$85 -> 1.2028051
AI26: =Calc!$B$86 -> Esfiharia | AO26: =Calc!$G$86 -> ██ | AT26: =Calc!$E$86 -> 0.030058427 | AV26: =Calc!$F$86 -> 0.57090146
AI27: =Calc!$B$87 -> Rotisserie | AO27: =Calc!$G$87 -> █ | AT27: =Calc!$E$87 -> 0.025504228 | AV27: =Calc!$F$87 -> 24.594303
AI28: =Calc!$B$88 -> Demais 24 segmentos | AO28: =Calc!$G$88 -> ██████ | AT28: =Calc!$E$88 -> 0.11666786 | AV28: =Calc!$F$88 -> -0.31225801
E32: Mix de produtos | AI32: Clientes ativos por mês
E33: =Calc!$B$120 -> Muçarela Mozzana 2 kg concentra 77,6% do faturamento | AI33: =Calc!$B$34 -> Pico de 301 clientes comprando em jul
E35: PRODUTO | J35: CÓD. | N35: PARTICIPAÇÃO | Q35: R$ | X35: VOLUME | Y35: CLIENTES | AA35: VS ANO ANT.
E36: =Calc!$A$110 -> Muçarela Mozzana 2 kg | J36: =Calc!$B$110 -> 4657 · 8556 | N36: =Calc!$I$110 -> ████████████ | P36: =Calc!$G$110 -> 0.77637452 | Q36: =Calc!$C$110 -> 2106489.5 | X36: =Calc!$E$110 -> 98709.32 | Y36: =Calc!$F$110 -> 343 | AA36: =Calc!$H$110 -> 0.66818211
E37: =Calc!$A$111 -> Muçarela Mozzalet 2 kg | J37: =Calc!$B$111 -> 4785 | N37: =Calc!$I$111 -> ██ | P37: =Calc!$G$111 -> 0.15543449 | Q37: =Calc!$C$111 -> 421730.89 | X37: =Calc!$E$111 -> 18254 | Y37: =Calc!$F$111 -> 42 | AA37: =Calc!$H$111 -> -0.53146502
E38: =Calc!$A$112 -> Chocolate em pó 50% 1 kg | J38: =Calc!$B$112 -> 4810 | N38: =Calc!$I$112 -> █ | P38: =Calc!$G$112 -> 0.030536203 | Q38: =Calc!$C$112 -> 82852.01 | X38: =Calc!$E$112 -> 1934.94 | Y38: =Calc!$F$112 -> 259 | AA38: =Calc!$H$112 -> 0.65934802
E39: =Calc!$A$113 -> Requeijão Pizzalet 1.8 kg | J39: =Calc!$B$113 -> 4701 | N39: =Calc!$I$113 -> █ | P39: =Calc!$G$113 -> 0.018744096 | Q39: =Calc!$C$113 -> 50857.21 | X39: =Calc!$E$113 -> 5646.96 | Y39: =Calc!$F$113 -> 20 | AA39: =Calc!$H$113 -> -0.42553887
E40: =Calc!$A$114 -> Composto lácteo Alibralac 1 kg | J40: =Calc!$B$114 -> 6335 | N40: =Calc!$I$114 -> █ | P40: =Calc!$G$114 -> 0.010407576 | Q40: =Calc!$C$114 -> 28238.24 | X40: =Calc!$E$114 -> 1146.48 | Y40: =Calc!$F$114 -> 29 | AA40: =Calc!$H$114 -> -0.0033631531
E41: =Calc!$A$115 -> Composto lácteo Merilú 400 g | J41: =Calc!$B$115 -> 6336 | N41: =Calc!$I$115 -> █ | P41: =Calc!$G$115 -> 0.0085031181 | Q41: =Calc!$C$115 -> 23070.99 | X41: =Calc!$E$115 -> 1206.66 | Y41: =Calc!$F$115 -> 35 | AA41: =Calc!$H$115 -> 0.25319886
E42: =Calc!$A$116 -> Parmesão ralado Parmozzana 1 kg | J42: =Calc!$B$116 -> 7891 · 8283 | N42: =Calc!$I$116 | P42: =Calc!$G$116 -> 0 | Q42: =Calc!$C$116 -> 0 | X42: =Calc!$E$116 -> 0 | Y42: =Calc!$F$116 -> 0 | AA42: =Calc!$H$116 -> sem venda
B45: Fonte: base de pedidos PMG Atacadista · Comparações sempre com o mesmo período do ano anterior · Mozzana 2 kg soma os códigos 4657 e 8556 · Segmentos com nomes duplicados foram unificados
B46: Novos = clientes que compraram o fornecedor na PMG pela primeira vez desde jan/2024 · Clientes e pedidos contados uma vez no período

Sheet Dados
A1: Ano | B1: Mes | C1: Familia | D1: Segmento | E1: Receita | F1: Kg | G1: Qtde | J1: Tipo | K1: Ano | L1: Mes | M1: Familia | N1: Segmento | O1: Clientes | P1: Pedidos | Q1: Novos | T1: Meses | U1: Anos | V1: Produtos | W1: Codigos | X1: Segmentos | Y1: UltimoMes | AA1: Fornecedor
A2: 2024 | B2: 1 | C2: Chocolate em pó 50% 1 kg | D2: Bar / Chopperia | E2: 56.04 | F2: 2.04 | G2: 2 | J2: A | K2: 2024 | L2: 1 | M2: Todos | N2: Todos | O2: 184 | P2: 458 | Q2: 184 | T2: jan | U2: 2024 | V2: Todos | X2: Todos | Y2: 12 | AA2: Alibra
A3: 2024 | B3: 1 | C3: Chocolate em pó 50% 1 kg | D3: Casa Noturna | E3: 27.8 | F3: 1.02 | G3: 1 | J3: M | K3: 2024 | L3: 1 | M3: Todos | N3: Todos | O3: 184 | P3: 458 | Q3: 0 | T3: fev | U3: 2025 | V3: Muçarela Mozzana 2 kg | W3: 4657 · 8556 | X3: Pizzaria | Y3: 12
A4: 2024 | B4: 1 | C4: Chocolate em pó 50% 1 kg | D4: Churrascaria | E4: 27.9 | F4: 1.02 | G4: 1 | J4: A | K4: 2024 | L4: 2 | M4: Todos | N4: Todos | O4: 245 | P4: 862 | Q4: 245 | T4: mar | U4: 2026 | V4: Muçarela Mozzalet 2 kg | W4: 4785 | X4: Restaurante / Cantina | Y4: 9
A5: 2024 | B5: 1 | C5: Chocolate em pó 50% 1 kg | D5: Hamburgueria | E5: 27.81 | F5: 1.02 | G5: 1 | J5: M | K5: 2024 | L5: 2 | M5: Todos | N5: Todos | O5: 190 | P5: 404 | Q5: 0 | T5: abr | V5: Requeijão Pizzalet 1,8 kg | W5: 4701 | X5: Cozinha Industrial
A6: 2024 | B6: 1 | C6: Chocolate em pó 50% 1 kg | D6: Hotel / Motel / Pousada | E6: 904 | F6: 33.66 | G6: 33 | J6: A | K6: 2024 | L6: 3 | M6: Todos | N6: Todos | O6: 301 | P6: 1292 | Q6: 301 | T6: mai | V6: Chocolate em pó 50% 1 kg | W6: 4810 | X6: Fábrica de Massas
A7: 2024 | B7: 1 | C7: Chocolate em pó 50% 1 kg | D7: Instituição Religiosa | E7: 112.08 | F7: 4.08 | G7: 4 | J7: M | K7: 2024 | L7: 3 | M7: Todos | N7: Todos | O7: 200 | P7: 430 | Q7: 0 | T7: jun | V7: Composto lácteo Alibralac 1 kg | W7: 6335 | X7: Outros
A8: 2024 | B8: 1 | C8: Chocolate em pó 50% 1 kg | D8: Lanchonete / Cafeteria | E8: 83.71 | F8: 3.06 | G8: 3 | J8: A | K8: 2024 | L8: 4 | M8: Todos | N8: Todos | O8: 353 | P8: 1826 | Q8: 353 | T8: jul | V8: Composto lácteo Merilú 400 g | W8: 6336 | X8: Pessoa Física
A9: 2024 | B9: 1 | C9: Chocolate em pó 50% 1 kg | D9: Outros | E9: 80.81 | F9: 3.06 | G9: 3 | J9: M | K9: 2024 | L9: 4 | M9: Todos | N9: Todos | O9: 214 | P9: 534 | Q9: 0 | T9: ago | V9: Parmesão ralado Parmozzana 1 kg | W9: 7891 · 8283 | X9: Pastelaria
A10: 2024 | B10: 1 | C10: Chocolate em pó 50% 1 kg | D10: Padaria | E10: 27 | F10: 1.02 | G10: 1 | J10: A | K10: 2024 | L10: 5 | M10: Todos | N10: Todos | O10: 409 | P10: 2321 | Q10: 409 | T10: set | X10: Esfiharia
A11: 2024 | B11: 1 | C11: Chocolate em pó 50% 1 kg | D11: Pizzaria | E11: 304.43 | F11: 11.22 | G11: 11 | J11: M | K11: 2024 | L11: 5 | M11: Todos | N11: Todos | O11: 224 | P11: 495 | Q11: 0 | T11: out | X11: Lanchonete / Cafeteria
A12: 2024 | B12: 1 | C12: Chocolate em pó 50% 1 kg | D12: Restaurante / Cantina | E12: 953.1 | F12: 34.68 | G12: 34 | J12: A | K12: 2024 | L12: 6 | M12: Todos | N12: Todos | O12: 479 | P12: 2859 | Q12: 479 | T12: nov | X12: Padaria
A13: 2024 | B13: 1 | C13: Chocolate em pó 50% 1 kg | D13: Supermercado | E13: 506.48 | F13: 18.36 | G13: 18 | J13: M | K13: 2024 | L13: 6 | M13: Todos | N13: Todos | O13: 252 | P13: 538 | Q13: 0 | T13: dez | X13: Supermercado
A14: 2024 | B14: 1 | C14: Composto lácteo Alibralac 1 kg | D14: Fábrica de Massas | E14: 95 | F14: 5.1 | G14: 5 | J14: A | K14: 2024 | L14: 7 | M14: Todos | N14: Todos | O14: 533 | P14: 3456 | Q14: 533 | X14: Rotisserie
A15: 2024 | B15: 1 | C15: Composto lácteo Alibralac 1 kg | D15: Hotel / Motel / Pousada | E15: 959.5 | F15: 51 | G15: 50 | J15: M | K15: 2024 | L15: 7 | M15: Todos | N15: Todos | O15: 257 | P15: 597 | Q15: 0 | X15: Mercearia / Sacolão
A16: 2024 | B16: 1 | C16: Composto lácteo Alibralac 1 kg | D16: Mercearia / Sacolão | E16: 76 | F16: 4.08 | G16: 4 | J16: A | K16: 2024 | L16: 8 | M16: Todos | N16: Todos | O16: 613 | P16: 4002 | Q16: 613 | X16: Buffet
A17: 2024 | B17: 1 | C17: Composto lácteo Alibralac 1 kg | D17: Pizzaria | E17: 760 | F17: 40.8 | G17: 40 | J17: M | K17: 2024 | L17: 8 | M17: Todos | N17: Todos | O17: 269 | P17: 546 | Q17: 0 | X17: Hotel / Motel / Pousada
A18: 2024 | B18: 1 | C18: Composto lácteo Merilú 400 g | D18: Casa Noturna | E18: 198.75 | F18: 10.5 | G18: 25 | J18: A | K18: 2024 | L18: 9 | M18: Todos | N18: Todos | O18: 662 | P18: 4525 | Q18: 662 | X18: Hamburgueria
A19: 2024 | B19: 1 | C19: Composto lácteo Merilú 400 g | D19: Churrascaria | E19: 79.3 | F19: 4.2 | G19: 10 | J19: M | K19: 2024 | L19: 9 | M19: Todos | N19: Todos | O19: 231 | P19: 523 | Q19: 0 | X19: Laticínios / Distribuidor
A20: 2024 | B20: 1 | C20: Composto lácteo Merilú 400 g | D20: Cozinha Industrial | E20: 382.5 | F20: 21.42 | G20: 51 | J20: A | K20: 2024 | L20: 10 | M20: Todos | N20: Todos | O20: 698 | P20: 5119 | Q20: 698 | X20: Cozinha Oriental
A21: 2024 | B21: 1 | C21: Composto lácteo Merilú 400 g | D21: Esfiharia | E21: 21.39 | F21: 1.26 | G21: 3 | J21: M | K21: 2024 | L21: 10 | M21: Todos | N21: Todos | O21: 247 | P21: 594 | Q21: 0 | X21: Adega
A22: 2024 | B22: 1 | C22: Composto lácteo Merilú 400 g | D22: Hamburgueria | E22: 819.95 | F22: 48.3 | G22: 115 | J22: A | K22: 2024 | L22: 11 | M22: Todos | N22: Todos | O22: 733 | P22: 5634 | Q22: 733 | X22: Bar / Chopperia
A23: 2024 | B23: 1 | C23: Composto lácteo Merilú 400 g | D23: Hospital / Casa de Repouso | E23: 22.5 | F23: 1.26 | G23: 3 | J23: M | K23: 2024 | L23: 11 | M23: Todos | N23: Todos | O23: 227 | P23: 515 | Q23: 0 | X23: Confeitaria
A24: 2024 | B24: 1 | C24: Composto lácteo Merilú 400 g | D24: Lanchonete / Cafeteria | E24: 23.07 | F24: 1.26 | G24: 3 | J24: A | K24: 2024 | L24: 12 | M24: Todos | N24: Todos | O24: 761 | P24: 6144 | Q24: 761 | X24: Distribuidor Alimentos
A25: 2024 | B25: 1 | C25: Composto lácteo Merilú 400 g | D25: Outros | E25: 233.64 | F25: 13.86 | G25: 33 | J25: M | K25: 2024 | L25: 12 | M25: Todos | N25: Todos | O25: 208 | P25: 510 | Q25: 0 | X25: Churrascaria
... A35: 2024 | B35: 1 | C35: Muçarela Mozzana 2 kg | D35: Confeitaria | E35: 79.14 | F35: 4.04 | G35: 2 | J35: M | K35: 2024 | L35: 5 | M35: Todos | N35: Pizzaria | O35: 81 | P35: 223 | Q35: 0 | X35: Açougue
A36: 2024 | B36: 1 | C36: Muçarela Mozzana 2 kg | D36: Cozinha Industrial | E36: 7566.54 | F36: 410.06 | G36: 203 | J36: A | K36: 2024 | L36: 6 | M36: Todos | N36: Pizzaria | O36: 149 | P36: 1294 | Q36: 149
A37: 2024 | B37: 1 | C37: Muçarela Mozzana 2 kg | D37: Cozinha Oriental | E37: 336.6 | F37: 18.18 | G37: 9 | J37: M | K37: 2024 | L37: 6 | M37: Todos | N37: Pizzaria | O37: 95 | P37: 246 | Q37: 0
A38: 2024 | B38: 1 | C38: Muçarela Mozzana 2 kg | D38: Esfiharia | E38: 2709.17 | F38: 143.42 | G38: 71 | J38: A | K38: 2024 | L38: 7 | M38: Todos | N38: Pizzaria | O38: 166 | P38: 1574 | Q38: 166
A39: 2024 | B39: 1 | C39: Muçarela Mozzana 2 kg | D39: Fábrica de Massas | E39: 19267.02 | F39: 1036.26 | G39: 513 | J39: M | K39: 2024 | L39: 7 | M39: Todos | N39: Pizzaria | O39: 97 | P39: 280 | Q39: 0
A40: 2024 | B40: 1 | C40: Muçarela Mozzana 2 kg | D40: Hamburgueria | E40: 1684.16 | F40: 88.88 | G40: 44 | J40: A | K40: 2024 | L40: 8 | M40: Todos | N40: Pizzaria | O40: 193 | P40: 1812 | Q40: 193
A41: 2024 | B41: 1 | C41: Muçarela Mozzana 2 kg | D41: Lanchonete / Cafeteria | E41: 407.5 | F41: 22.22 | G41: 11 | J41: M | K41: 2024 | L41: 8 | M41: Todos | N41: Pizzaria | O41: 99 | P41: 238 | Q41: 0
A42: 2024 | B42: 1 | C42: Muçarela Mozzana 2 kg | D42: Laticínios / Distribuidor | E42: 2042.46 | F42: 109.08 | G42: 54 | J42: A | K42: 2024 | L42: 9 | M42: Todos | N42: Pizzaria | O42: 206 | P42: 2050 | Q42: 206
A43: 2024 | B43: 1 | C43: Muçarela Mozzana 2 kg | D43: Loja de Conveniência | E43: 756 | F43: 40.4 | G43: 20 | J43: M | K43: 2024 | L43: 9 | M43: Todos | N43: Pizzaria | O43: 88 | P43: 238 | Q43: 0
A44: 2024 | B44: 1 | C44: Muçarela Mozzana 2 kg | D44: Mercearia / Sacolão | E44: 2122.83 | F44: 115.14 | G44: 57 | J44: A | K44: 2024 | L44: 10 | M44: Todos | N44: Pizzaria | O44: 216 | P44: 2324 | Q44: 216
A45: 2024 | B45: 1 | C45: Muçarela Mozzana 2 kg | D45: Outros | E45: 18277.8 | F45: 969.6 | G45: 480 | J45: M | K45: 2024 | L45: 10 | M45: Todos | N45: Pizzaria | O45: 91 | P45: 274 | Q45: 0
A46: 2024 | B46: 1 | C46: Muçarela Mozzana 2 kg | D46: Padaria | E46: 2619.82 | F46: 137.36 | G46: 68 | J46: A | K46: 2024 | L46: 11 | M46: Todos | N46: Pizzaria | O46: 235 | P46: 2564 | Q46: 235
A47: 2024 | B47: 1 | C47: Muçarela Mozzana 2 kg | D47: Pastelaria | E47: 1667.52 | F47: 84.84 | G47: 42 | J47: M | K47: 2024 | L47: 11 | M47: Todos | N47: Pizzaria | O47: 95 | P47: 240 | Q47: 0
... A1841: 2026 | B1841: 9 | C1841: Muçarela Mozzana 2 kg | D1841: Supermercado | E1841: 4255.73 | F1841: 179.78 | G1841: 89 | J1841: A | K1841: 2024 | L1841: 6 | M1841: Chocolate em pó 50% 1 kg | N1841: Laticínios / Distribuidor | O1841: 1 | P1841: 1 | Q1841: 1
J1842: A | K1842: 2024 | L1842: 7 | M1842: Chocolate em pó 50% 1 kg | N1842: Laticínios / Distribuidor | O1842: 1 | P1842: 1 | Q1842: 1
...

Sheet Calc
A1: Ano | B1: =Dashboard!$B$7 -> 2026
A2: MesSel | B2: =IFERROR(MATCH(Dashboard!$H$7,Dados!$T$2:$T$13,0),12) -> 9
A3: UltMes | B3: =INDEX(Dados!$Y$2:$Y$4,MATCH(B1,Dados!$U$2:$U$4,0)) -> 9
A4: MesEf | B4: =MIN(B2,B3) -> 9
A5: Prod | B5: =Dashboard!$K$7 -> Todos
A6: Seg | B6: =Dashboard!$V$7 -> Todos
A7: ProdCrit | B7: =IF(B5="Todos","*",B5) -> *
A8: SegCrit | B8: =IF(B6="Todos","*",B6) -> *
A9: AnoAnt | B9: =B1-1 -> 2025
A10: TemAnt | B10: =B1>MIN(Dados!$U$2:$U$4) -> TRUE
A12: Receita | B12: =SUMIFS(Dados!$E$2:$E$1841,Dados!$A$2:$A$1841,$B$1,Dados!$B$2:$B$1841,"<="&$B$4,Dados!$C$2:$C$1841,$B$7,Dados!$D$2:$D$1841,$B$8) -> 2713238.8 | C12: =IF($B$10,SUMIFS(Dados!$E$2:$E$1841,Dados!$A$2:$A$1841,$B$9,Dados!$B$2:$B$1841,"<="&$B$4,Dados!$C$2:$C$1841,$B$7,Dados!$D$2:$D$1841,$B$8),0) -> 2353832.9 | D12: =IF(AND($B$10,C12>0),B12/C12-1,"") -> 0.15268965 | E12: =IF(C12>0,C12,"") -> 2353832.9
A13: Kg | B13: =SUMIFS(Dados!$F$2:$F$1841,Dados!$A$2:$A$1841,$B$1,Dados!$B$2:$B$1841,"<="&$B$4,Dados!$C$2:$C$1841,$B$7,Dados!$D$2:$D$1841,$B$8) -> 126898.36 | C13: =IF($B$10,SUMIFS(Dados!$F$2:$F$1841,Dados!$A$2:$A$1841,$B$9,Dados!$B$2:$B$1841,"<="&$B$4,Dados!$C$2:$C$1841,$B$7,Dados!$D$2:$D$1841,$B$8),0) -> 108045.2 | D13: =IF(AND($B$10,C13>0),B13/C13-1,"") -> 0.17449327 | E13: =IF(C13>0,C13,"") -> 108045.2
A14: Clientes | B14: =SUMIFS(Dados!$O$2:$O$7405,Dados!$J$2:$J$7405,"A",Dados!$K$2:$K$7405,$B$1,Dados!$L$2:$L$7405,$B$4,Dados!$M$2:$M$7405,$B$5,Dados!$N$2:$N$7405,$B$6) -> 674 | C14: =IF($B$10,SUMIFS(Dados!$O$2:$O$7405,Dados!$J$2:$J$7405,"A",Dados!$K$2:$K$7405,$B$9,Dados!$L$2:$L$7405,$B$4,Dados!$M$2:$M$7405,$B$5,Dados!$N$2:$N$7405,$B$6),0) -> 600 | D14: =IF(AND($B$10,C14>0),B14/C14-1,"") -> 0.12333333 | E14: =IF(C14>0,C14,"") -> 600
A15: Pedidos | B15: =SUMIFS(Dados!$P$2:$P$7405,Dados!$J$2:$J$7405,"A",Dados!$K$2:$K$7405,$B$1,Dados!$L$2:$L$7405,$B$4,Dados!$M$2:$M$7405,$B$5,Dados!$N$2:$N$7405,$B$6) -> 4635 | C15: =IF($B$10,SUMIFS(Dados!$P$2:$P$7405,Dados!$J$2:$J$7405,"A",Dados!$K$2:$K$7405,$B$9,Dados!$L$2:$L$7405,$B$4,Dados!$M$2:$M$7405,$B$5,Dados!$N$2:$N$7405,$B$6),0) -> 4258 | D15: =IF(AND($B$10,C15>0),B15/C15-1,"") -> 0.08853922 | E15: =IF(C15>0,C15,"") -> 4258
A16: Novos | B16: =IF($B$10,SUMIFS(Dados!$Q$2:$Q$7405,Dados!$J$2:$J$7405,"A",Dados!$K$2:$K$7405,$B$1,Dados!$L$2:$L$7405,$B$4,Dados!$M$2:$M$7405,$B$5,Dados!$N$2:$N$7405,$B$6),"") -> 385
A17: Ticket | B17: =IFERROR(B12/B15,0) -> 585.38054 | C17: =IFERROR(C12/C15,0) -> 552.80246 | D17: =IF(AND($B$10,C17>0),B17/C17-1,"") -> 0.058932585 | E17: =IF(C17>0,C17,"") -> 552.80246
A19: Mes | B19: =""&Dados!$U$2 -> 2024 | C19: =""&Dados!$U$3 -> 2025 | D19: =""&Dados!$U$4 -> 2026 | E19: =""&$B$1 -> 2026 | F19: =""&$B$9 -> 2025
A20: jan | B20: =IF(1>Dados!$Y$2,NA(),SUMIFS(Dados!$E$2:$E$1841,Dados!$A$2:$A$1841,Dados!$U$2,Dados!$B$2:$B$1841,1,Dados!$C$2:$C$1841,$B$7,Dados!$D$2:$D$1841,$B$8)) -> 190167.02 | C20: =IF(1>Dados!$Y$3,NA(),SUMIFS(Dados!$E$2:$E$1841,Dados!$A$2:$A$1841,Dados!$U$3,Dados!$B$2:$B$1841,1,Dados!$C$2:$C$1841,$B$7,Dados!$D$2:$D$1841,$B$8)) -> 284611.68 | D20: =IF(1>Dados!$Y$4,NA(),SUMIFS(Dados!$E$2:$E$1841,Dados!$A$2:$A$1841,Dados!$U$4,Dados!$B$2:$B$1841,1,Dados!$C$2:$C$1841,$B$7,Dados!$D$2:$D$1841,$B$8)) -> 219545.26 | E20: =IF(1>$B$4,NA(),SUMIFS(Dados!$O$2:$O$7405,Dados!$J$2:$J$7405,"M",Dados!$K$2:$K$7405,$B$1,Dados!$L$2:$L$7405,1,Dados!$M$2:$M$7405,$B$5,Dados!$N$2:$N$7405,$B$6)) -> 177 | F20: =IF(OR(1>$B$4,NOT($B$10)),NA(),SUMIFS(Dados!$O$2:$O$7405,Dados!$J$2:$J$7405,"M",Dados!$K$2:$K$7405,$B$9,Dados!$L$2:$L$7405,1,Dados!$M$2:$M$7405,$B$5,Dados!$N$2:$N$7405,$B$6)) -> 210 | G20: =IF(ISNUMBER(E20),E20,0) -> 177 | H20: =IF(1>$B$4,0,SUMIFS(Dados!$E$2:$E$1841,Dados!$A$2:$A$1841,$B$1,Dados!$B$2:$B$1841,1,Dados!$C$2:$C$1841,$B$7,Dados!$D$2:$D$1841,$B$8)) -> 219545.26
A21: fev | B21: =IF(2>Dados!$Y$2,NA(),SUMIFS(Dados!$E$2:$E$1841,Dados!$A$2:$A$1841,Dados!$U$2,Dados!$B$2:$B$1841,2,Dados!$C$2:$C$1841,$B$7,Dados!$D$2:$D$1841,$B$8)) -> 176951.75 | C21: =IF(2>Dados!$Y$3,NA(),SUMIFS(Dados!$E$2:$E$1841,Dados!$A$2:$A$1841,Dados!$U$3,Dados!$B$2:$B$1841,2,Dados!$C$2:$C$1841,$B$7,Dados!$D$2:$D$1841,$B$8)) -> 268227.68 | D21: =IF(2>Dados!$Y$4,NA(),SUMIFS(Dados!$E$2:$E$1841,Dados!$A$2:$A$1841,Dados!$U$4,Dados!$B$2:$B$1841,2,Dados!$C$2:$C$1841,$B$7,Dados!$D$2:$D$1841,$B$8)) -> 172340.11 | E21: =IF(2>$B$4,NA(),SUMIFS(Dados!$O$2:$O$7405,Dados!$J$2:$J$7405,"M",Dados!$K$2:$K$7405,$B$1,Dados!$L$2:$L$7405,2,Dados!$M$2:$M$7405,$B$5,Dados!$N$2:$N$7405,$B$6)) -> 190 | F21: =IF(OR(2>$B$4,NOT($B$10)),NA(),SUMIFS(Dados!$O$2:$O$7405,Dados!$J$2:$J$7405,"M",Dados!$K$2:$K$7405,$B$9,Dados!$L$2:$L$7405,2,Dados!$M$2:$M$7405,$B$5,Dados!$N$2:$N$7405,$B$6)) -> 227 | G21: =IF(ISNUMBER(E21),E21,0) -> 190 | H21: =IF(2>$B$4,0,SUMIFS(Dados!$E$2:$E$1841,Dados!$A$2:$A$1841,$B$1,Dados!$B$2:$B$1841,2,Dados!$C$2:$C$1841,$B$7,Dados!$D$2:$D$1841,$B$8)) -> 172340.11
A22: mar | B22: =IF(3>Dados!$Y$2,NA(),SUMIFS(Dados!$E$2:$E$1841,Dados!$A$2:$A$1841,Dados!$U$2,Dados!$B$2:$B$1841,3,Dados!$C$2:$C$1841,$B$7,Dados!$D$2:$D$1841,$B$8)) -> 191008.75 | C22: =IF(3>Dados!$Y$3,NA(),SUMIFS(Dados!$E$2:$E$1841,Dados!$A$2:$A$1841,Dados!$U$3,Dados!$B$2:$B$1841,3,Dados!$C$2:$C$1841,$B$7,Dados!$D$2:$D$1841,$B$8)) -> 237177.79 | D22: =IF(3>Dados!$Y$4,NA(),SUMIFS(Dados!$E$2:$E$1841,Dados!$A$2:$A$1841,Dados!$U$4,Dados!$B$2:$B$1841,3,Dados!$C$2:$C$1841,$B$7,Dados!$D$2:$D$1841,$B$8)) -> 289865.78 | E22: =IF(3>$B$4,NA(),SUMIFS(Dados!$O$2:$O$7405,Dados!$J$2:$J$7405,"M",Dados!$K$2:$K$7405,$B$1,Dados!$L$2:$L$7405,3,Dados!$M$2:$M$7405,$B$5,Dados!$N$2:$N$7405,$B$6)) -> 245 | F22: =IF(OR(3>$B$4,NOT($B$10)),NA(),SUMIFS(Dados!$O$2:$O$7405,Dados!$J$2:$J$7405,"M",Dados!$K$2:$K$7405,$B$9,Dados!$L$2:$L$7405,3,Dados!$M$2:$M$7405,$B$5,Dados!$N$2:$N$7405,$B$6)) -> 187 | G22: =IF(ISNUMBER(E22),E22,0) -> 245 | H22: =IF(3>$B$4,0,SUMIFS(Dados!$E$2:$E$1841,Dados!$A$2:$A$1841,$B$1,Dados!$B$2:$B$1841,3,Dados!$C$2:$C$1841,$B$7,Dados!$D$2:$D$1841,$B$8)) -> 289865.78
A23: abr | B23: =IF(4>Dados!$Y$2,NA(),SUMIFS(Dados!$E$2:$E$1841,Dados!$A$2:$A$1841,Dados!$U$2,Dados!$B$2:$B$1841,4,Dados!$C$2:$C$1841,$B$7,Dados!$D$2:$D$1841,$B$8)) -> 255943.64 | C23: =IF(4>Dados!$Y$3,NA(),SUMIFS(Dados!$E$2:$E$1841,Dados!$A$2:$A$1841,Dados!$U$3,Dados!$B$2:$B$1841,4,Dados!$C$2:$C$1841,$B$7,Dados!$D$2:$D$1841,$B$8)) -> 273130.98 | D23: =IF(4>Dados!$Y$4,NA(),SUMIFS(Dados!$E$2:$E$1841,Dados!$A$2:$A$1841,Dados!$U$4,Dados!$B$2:$B$1841,4,Dados!$C$2:$C$1841,$B$7,Dados!$D$2:$D$1841,$B$8)) -> 303138.86 | E23: =IF(4>$B$4,NA(),SUMIFS(Dados!$O$2:$O$7405,Dados!$J$2:$J$7405,"M",Dados!$K$2:$K$7405,$B$1,Dados!$L$2:$L$7405,4,Dados!$M$2:$M$7405,$B$5,Dados!$N$2:$N$7405,$B$6)) -> 196 | F23: =IF(OR(4>$B$4,NOT($B$10)),NA(),SUMIFS(Dados!$O$2:$O$7405,Dados!$J$2:$J$7405,"M",Dados!$K$2:$K$7405,$B$9,Dados!$L$2:$L$7405,4,Dados!$M$2:$M$7405,$B$5,Dados!$N$2:$N$7405,$B$6)) -> 166 | G23: =IF(ISNUMBER(E23),E23,0) -> 196 | H23: =IF(4>$B$4,0,SUMIFS(Dados!$E$2:$E$1841,Dados!$A$2:$A$1841,$B$1,Dados!$B$2:$B$1841,4,Dados!$C$2:$C$1841,$B$7,Dados!$D$2:$D$1841,$B$8)) -> 303138.86
A24: mai | B24: =IF(5>Dados!$Y$2,NA(),SUMIFS(Dados!$E$2:$E$1841,Dados!$A$2:$A$1841,Dados!$U$2,Dados!$B$2:$B$1841,5,Dados!$C$2:$C$1841,$B$7,Dados!$D$2:$D$1841,$B$8)) -> 266888.81 | C24: =IF(5>Dados!$Y$3,NA(),SUMIFS(Dados!$E$2:$E$1841,Dados!$A$2:$A$1841,Dados!$U$3,Dados!$B$2:$B$1841,5,Dados!$C$2:$C$1841,$B$7,Dados!$D$2:$D$1841,$B$8)) -> 260637.89 | D24: =IF(5>Dados!$Y$4,NA(),SUMIFS(Dados!$E$2:$E$1841,Dados!$A$2:$A$1841,Dados!$U$4,Dados!$B$2:$B$1841,5,Dados!$C$2:$C$1841,$B$7,Dados!$D$2:$D$1841,$B$8)) -> 290237.59 | E24: =IF(5>$B$4,NA(),SUMIFS(Dados!$O$2:$O$7405,Dados!$J$2:$J$7405,"M",Dados!$K$2:$K$7405,$B$1,Dados!$L$2:$L$7405,5,Dados!$M$2:$M$7405,$B$5,Dados!$N$2:$N$7405,$B$6)) -> 248 | F24: =IF(OR(5>$B$4,NOT($B$10)),NA(),SUMIFS(Dados!$O$2:$O$7405,Dados!$J$2:$J$7405,"M",Dados!$K$2:$K$7405,$B$9,Dados!$L$2:$L$7405,5,Dados!$M$2:$M$7405,$B$5,Dados!$N$2:$N$7405,$B$6)) -> 204 | G24: =IF(ISNUMBER(E24),E24,0) -> 248 | H24: =IF(5>$B$4,0,SUMIFS(Dados!$E$2:$E$1841,Dados!$A$2:$A$1841,$B$1,Dados!$B$2:$B$1841,5,Dados!$C$2:$C$1841,$B$7,Dados!$D$2:$D$1841,$B$8)) -> 290237.59
A25: jun | B25: =IF(6>Dados!$Y$2,NA(),SUMIFS(Dados!$E$2:$E$1841,Dados!$A$2:$A$1841,Dados!$U$2,Dados!$B$2:$B$1841,6,Dados!$C$2:$C$1841,$B$7,Dados!$D$2:$D$1841,$B$8)) -> 291887.91 | C25: =IF(6>Dados!$Y$3,NA(),SUMIFS(Dados!$E$2:$E$1841,Dados!$A$2:$A$1841,Dados!$U$3,Dados!$B$2:$B$1841,6,Dados!$C$2:$C$1841,$B$7,Dados!$D$2:$D$1841,$B$8)) -> 278179.88 | D25: =IF(6>Dados!$Y$4,NA(),SUMIFS(Dados!$E$2:$E$1841,Dados!$A$2:$A$1841,Dados!$U$4,Dados!$B$2:$B$1841,6,Dados!$C$2:$C$1841,$B$7,Dados!$D$2:$D$1841,$B$8)) -> 345357.26 | E25: =IF(6>$B$4,NA(),SUMIFS(Dados!$O$2:$O$7405,Dados!$J$2:$J$7405,"M",Dados!$K$2:$K$7405,$B$1,Dados!$L$2:$L$7405,6,Dados!$M$2:$M$7405,$B$5,Dados!$N$2:$N$7405,$B$6)) -> 289 | F25: =IF(OR(6>$B$4,NOT($B$10)),NA(),SUMIFS(Dados!$O$2:$O$7405,Dados!$J$2:$J$7405,"M",Dados!$K$2:$K$7405,$B$9,Dados!$L$2:$L$7405,6,Dados!$M$2:$M$7405,$B$5,Dados!$N$2:$N$7405,$B$6)) -> 204 | G25: =IF(ISNUMBER(E25),E25,0) -> 289 | H25: =IF(6>$B$4,0,SUMIFS(Dados!$E$2:$E$1841,Dados!$A$2:$A$1841,$B$1,Dados!$B$2:$B$1841,6,Dados!$C$2:$C$1841,$B$7,Dados!$D$2:$D$1841,$B$8)) -> 345357.26
A26: jul | B26: =IF(7>Dados!$Y$2,NA(),SUMIFS(Dados!$E$2:$E$1841,Dados!$A$2:$A$1841,Dados!$U$2,Dados!$B$2:$B$1841,7,Dados!$C$2:$C$1841,$B$7,Dados!$D$2:$D$1841,$B$8)) -> 261634.16 | C26: =IF(7>Dados!$Y$3,NA(),SUMIFS(Dados!$E$2:$E$1841,Dados!$A$2:$A$1841,Dados!$U$3,Dados!$B$2:$B$1841,7,Dados!$C$2:$C$1841,$B$7,Dados!$D$2:$D$1841,$B$8)) -> 243883.55 | D26: =IF(7>Dados!$Y$4,NA(),SUMIFS(Dados!$E$2:$E$1841,Dados!$A$2:$A$1841,Dados!$U$4,Dados!$B$2:$B$1841,7,Dados!$C$2:$C$1841,$B$7,Dados!$D$2:$D$1841,$B$8)) -> 349927.13 | E26: =IF(7>$B$4,NA(),SUMIFS(Dados!$O$2:$O$7405,Dados!$J$2:$J$7405,"M",Dados!$K$2:$K$7405,$B$1,Dados!$L$2:$L$7405,7,Dados!$M$2:$M$7405,$B$5,Dados!$N$2:$N$7405,$B$6)) -> 301 | F26: =IF(OR(7>$B$4,NOT($B$10)),NA(),SUMIFS(Dados!$O$2:$O$7405,Dados!$J$2:$J$7405,"M",Dados!$K$2:$K$7405,$B$9,Dados!$L$2:$L$7405,7,Dados!$M$2:$M$7405,$B$5,Dados!$N$2:$N$7405,$B$6)) -> 240 | G26: =IF(ISNUMBER(E26),E26,0) -> 301 | H26: =IF(7>$B$4,0,SUMIFS(Dados!$E$2:$E$1841,Dados!$A$2:$A$1841,$B$1,Dados!$B$2:$B$1841,7,Dados!$C$2:$C$1841,$B$7,Dados!$D$2:$D$1841,$B$8)) -> 349927.13
A27: ago | B27: =IF(8>Dados!$Y$2,NA(),SUMIFS(Dados!$E$2:$E$1841,Dados!$A$2:$A$1841,Dados!$U$2,Dados!$B$2:$B$1841,8,Dados!$C$2:$C$1841,$B$7,Dados!$D$2:$D$1841,$B$8)) -> 261835.44 | C27: =IF(8>Dados!$Y$3,NA(),SUMIFS(Dados!$E$2:$E$1841,Dados!$A$2:$A$1841,Dados!$U$3,Dados!$B$2:$B$1841,8,Dados!$C$2:$C$1841,$B$7,Dados!$D$2:$D$1841,$B$8)) -> 239607.48 | D27: =IF(8>Dados!$Y$4,NA(),SUMIFS(Dados!$E$2:$E$1841,Dados!$A$2:$A$1841,Dados!$U$4,Dados!$B$2:$B$1841,8,Dados!$C$2:$C$1841,$B$7,Dados!$D$2:$D$1841,$B$8)) -> 351854.01 | E27: =IF(8>$B$4,NA(),SUMIFS(Dados!$O$2:$O$7405,Dados!$J$2:$J$7405,"M",Dados!$K$2:$K$7405,$B$1,Dados!$L$2:$L$7405,8,Dados!$M$2:$M$7405,$B$5,Dados!$N$2:$N$7405,$B$6)) -> 211 | F27: =IF(OR(8>$B$4,NOT($B$10)),NA(),SUMIFS(Dados!$O$2:$O$7405,Dados!$J$2:$J$7405,"M",Dados!$K$2:$K$7405,$B$9,Dados!$L$2:$L$7405,8,Dados!$M$2:$M$7405,$B$5,Dados!$N$2:$N$7405,$B$6)) -> 223 | G27: =IF(ISNUMBER(E27),E27,0) -> 211 | H27: =IF(8>$B$4,0,SUMIFS(Dados!$E$2:$E$1841,Dados!$A$2:$A$1841,$B$1,Dados!$B$2:$B$1841,8,Dados!$C$2:$C$1841,$B$7,Dados!$D$2:$D$1841,$B$8)) -> 351854.01
A28: set | B28: =IF(9>Dados!$Y$2,NA(),SUMIFS(Dados!$E$2:$E$1841,Dados!$A$2:$A$1841,Dados!$U$2,Dados!$B$2:$B$1841,9,Dados!$C$2:$C$1841,$B$7,Dados!$D$2:$D$1841,$B$8)) -> 282479.13 | C28: =IF(9>Dados!$Y$3,NA(),SUMIFS(Dados!$E$2:$E$1841,Dados!$A$2:$A$1841,Dados!$U$3,Dados!$B$2:$B$1841,9,Dados!$C$2:$C$1841,$B$7,Dados!$D$2:$D$1841,$B$8)) -> 268375.96 | D28: =IF(9>Dados!$Y$4,NA(),SUMIFS(Dados!$E$2:$E$1841,Dados!$A$2:$A$1841,Dados!$U$4,Dados!$B$2:$B$1841,9,Dados!$C$2:$C$1841,$B$7,Dados!$D$2:$D$1841,$B$8)) -> 390972.81 | E28: =IF(9>$B$4,NA(),SUMIFS(Dados!$O$2:$O$7405,Dados!$J$2:$J$7405,"M",Dados!$K$2:$K$7405,$B$1,Dados!$L$2:$L$7405,9,Dados!$M$2:$M$7405,$B$5,Dados!$N$2:$N$7405,$B$6)) -> 184 | F28: =IF(OR(9>$B$4,NOT($B$10)),NA(),SUMIFS(Dados!$O$2:$O$7405,Dados!$J$2:$J$7405,"M",Dados!$K$2:$K$7405,$B$9,Dados!$L$2:$L$7405,9,Dados!$M$2:$M$7405,$B$5,Dados!$N$2:$N$7405,$B$6)) -> 220 | G28: =IF(ISNUMBER(E28),E28,0) -> 184 | H28: =IF(9>$B$4,0,SUMIFS(Dados!$E$2:$E$1841,Dados!$A$2:$A$1841,$B$1,Dados!$B$2:$B$1841,9,Dados!$C$2:$C$1841,$B$7,Dados!$D$2:$D$1841,$B$8)) -> 390972.81
A29: out | B29: =IF(10>Dados!$Y$2,NA(),SUMIFS(Dados!$E$2:$E$1841,Dados!$A$2:$A$1841,Dados!$U$2,Dados!$B$2:$B$1841,10,Dados!$C$2:$C$1841,$B$7,Dados!$D$2:$D$1841,$B$8)) -> 332189.5 | C29: =IF(10>Dados!$Y$3,NA(),SUMIFS(Dados!$E$2:$E$1841,Dados!$A$2:$A$1841,Dados!$U$3,Dados!$B$2:$B$1841,10,Dados!$C$2:$C$1841,$B$7,Dados!$D$2:$D$1841,$B$8)) -> 268497.1 | D29: =IF(10>Dados!$Y$4,NA(),SUMIFS(Dados!$E$2:$E$1841,Dados!$A$2:$A$1841,Dados!$U$4,Dados!$B$2:$B$1841,10,Dados!$C$2:$C$1841,$B$7,Dados!$D$2:$D$1841,$B$8)) -> #N/A | E29: =IF(10>$B$4,NA(),SUMIFS(Dados!$O$2:$O$7405,Dados!$J$2:$J$7405,"M",Dados!$K$2:$K$7405,$B$1,Dados!$L$2:$L$7405,10,Dados!$M$2:$M$7405,$B$5,Dados!$N$2:$N$7405,$B$6)) -> #N/A | F29: =IF(OR(10>$B$4,NOT($B$10)),NA(),SUMIFS(Dados!$O$2:$O$7405,Dados!$J$2:$J$7405,"M",Dados!$K$2:$K$7405,$B$9,Dados!$L$2:$L$7405,10,Dados!$M$2:$M$7405,$B$5,Dados!$N$2:$N$7405,$B$6)) -> #N/A | G29: =IF(ISNUMBER(E29),E29,0) -> 0 | H29: =IF(10>$B$4,0,SUMIFS(Dados!$E$2:$E$1841,Dados!$A$2:$A$1841,$B$1,Dados!$B$2:$B$1841,10,Dados!$C$2:$C$1841,$B$7,Dados!$D$2:$D$1841,$B$8)) -> 0
A30: nov | B30: =IF(11>Dados!$Y$2,NA(),SUMIFS(Dados!$E$2:$E$1841,Dados!$A$2:$A$1841,Dados!$U$2,Dados!$B$2:$B$1841,11,Dados!$C$2:$C$1841,$B$7,Dados!$D$2:$D$1841,$B$8)) -> 290484.33 | C30: =IF(11>Dados!$Y$3,NA(),SUMIFS(Dados!$E$2:$E$1841,Dados!$A$2:$A$1841,Dados!$U$3,Dados!$B$2:$B$1841,11,Dados!$C$2:$C$1841,$B$7,Dados!$D$2:$D$1841,$B$8)) -> 221817.2 | D30: =IF(11>Dados!$Y$4,NA(),SUMIFS(Dados!$E$2:$E$1841,Dados!$A$2:$A$1841,Dados!$U$4,Dados!$B$2:$B$1841,11,Dados!$C$2:$C$1841,$B$7,Dados!$D$2:$D$1841,$B$8)) -> #N/A | E30: =IF(11>$B$4,NA(),SUMIFS(Dados!$O$2:$O$7405,Dados!$J$2:$J$7405,"M",Dados!$K$2:$K$7405,$B$1,Dados!$L$2:$L$7405,11,Dados!$M$2:$M$7405,$B$5,Dados!$N$2:$N$7405,$B$6)) -> #N/A | F30: =IF(OR(11>$B$4,NOT($B$10)),NA(),SUMIFS(Dados!$O$2:$O$7405,Dados!$J$2:$J$7405,"M",Dados!$K$2:$K$7405,$B$9,Dados!$L$2:$L$7405,11,Dados!$M$2:$M$7405,$B$5,Dados!$N$2:$N$7405,$B$6)) -> #N/A | G30: =IF(ISNUMBER(E30),E30,0) -> 0 | H30: =IF(11>$B$4,0,SUMIFS(Dados!$E$2:$E$1841,Dados!$A$2:$A$1841,$B$1,Dados!$B$2:$B$1841,11,Dados!$C$2:$C$1841,$B$7,Dados!$D$2:$D$1841,$B$8)) -> 0
A31: dez | B31: =IF(12>Dados!$Y$2,NA(),SUMIFS(Dados!$E$2:$E$1841,Dados!$A$2:$A$1841,Dados!$U$2,Dados!$B$2:$B$1841,12,Dados!$C$2:$C$1841,$B$7,Dados!$D$2:$D$1841,$B$8)) -> 286858.07 | C31: =IF(12>Dados!$Y$3,NA(),SUMIFS(Dados!$E$2:$E$1841,Dados!$A$2:$A$1841,Dados!$U$3,Dados!$B$2:$B$1841,12,Dados!$C$2:$C$1841,$B$7,Dados!$D$2:$D$1841,$B$8)) -> 187399.93 | D31: =IF(12>Dados!$Y$4,NA(),SUMIFS(Dados!$E$2:$E$1841,Dados!$A$2:$A$1841,Dados!$U$4,Dados!$B$2:$B$1841,12,Dados!$C$2:$C$1841,$B$7,Dados!$D$2:$D$1841,$B$8)) -> #N/A | E31: =IF(12>$B$4,NA(),SUMIFS(Dados!$O$2:$O$7405,Dados!$J$2:$J$7405,"M",Dados!$K$2:$K$7405,$B$1,Dados!$L$2:$L$7405,12,Dados!$M$2:$M$7405,$B$5,Dados!$N$2:$N$7405,$B$6)) -> #N/A | F31: =IF(OR(12>$B$4,NOT($B$10)),NA(),SUMIFS(Dados!$O$2:$O$7405,Dados!$J$2:$J$7405,"M",Dados!$K$2:$K$7405,$B$9,Dados!$L$2:$L$7405,12,Dados!$M$2:$M$7405,$B$5,Dados!$N$2:$N$7405,$B$6)) -> #N/A | G31: =IF(ISNUMBER(E31),E31,0) -> 0 | H31: =IF(12>$B$4,0,SUMIFS(Dados!$E$2:$E$1841,Dados!$A$2:$A$1841,$B$1,Dados!$B$2:$B$1841,12,Dados!$C$2:$C$1841,$B$7,Dados!$D$2:$D$1841,$B$8)) -> 0
A33: MelhorMes | B33: =IFERROR("Melhor mês de "&$B$1&": "&INDEX(Dados!$T$2:$T$13,MATCH(MAX(H20:H31),H20:H31,0))&"/"&RIGHT($B$1,2)&" · R$ "&FIXED(MAX(H20:H31)/1000,0)&" mil","") -> Melhor mês de 2026: set/26 · R$ 391 mil
A34: PicoCli | B34: =IFERROR(IF(MAX(G20:G31)=0,"","Pico de "&MAX(G20:G31)&" clientes comprando em "&INDEX(Dados!$T$2:$T$13,MATCH(MAX(G20:G31),G20:G31,0))),"") -> Pico de 301 clientes comprando em jul
A40: =Dados!$X$3 -> Pizzaria | B40: =SUMIFS(Dados!$E$2:$E$1841,Dados!$A$2:$A$1841,$B$1,Dados!$B$2:$B$1841,"<="&$B$4,Dados!$C$2:$C$1841,$B$7,Dados!$D$2:$D$1841,A40) -> 1126847.8 | C40: =IF($B$10,SUMIFS(Dados!$E$2:$E$1841,Dados!$A$2:$A$1841,$B$9,Dados!$B$2:$B$1841,"<="&$B$4,Dados!$C$2:$C$1841,$B$7,Dados!$D$2:$D$1841,A40),0) -> 827944.5 | D40: =B40+(1000-ROW())/1000000000 -> 1126847.8 | F40: Total | G40: =SUM($B$40:$B$72) -> 2713238.8
A41: =Dados!$X$4 -> Restaurante / Cantina | B41: =SUMIFS(Dados!$E$2:$E$1841,Dados!$A$2:$A$1841,$B$1,Dados!$B$2:$B$1841,"<="&$B$4,Dados!$C$2:$C$1841,$B$7,Dados!$D$2:$D$1841,A41) -> 481499.61 | C41: =IF($B$10,SUMIFS(Dados!$E$2:$E$1841,Dados!$A$2:$A$1841,$B$9,Dados!$B$2:$B$1841,"<="&$B$4,Dados!$C$2:$C$1841,$B$7,Dados!$D$2:$D$1841,A41),0) -> 510454.23 | D41: =B41+(1000-ROW())/1000000000 -> 481499.61 | G41: =SUM($C$40:$C$72) -> 2353832.9
A42: =Dados!$X$5 -> Cozinha Industrial | B42: =SUMIFS(Dados!$E$2:$E$1841,Dados!$A$2:$A$1841,$B$1,Dados!$B$2:$B$1841,"<="&$B$4,Dados!$C$2:$C$1841,$B$7,Dados!$D$2:$D$1841,A42) -> 323229.13 | C42: =IF($B$10,SUMIFS(Dados!$E$2:$E$1841,Dados!$A$2:$A$1841,$B$9,Dados!$B$2:$B$1841,"<="&$B$4,Dados!$C$2:$C$1841,$B$7,Dados!$D$2:$D$1841,A42),0) -> 125528.68 | D42: =B42+(1000-ROW())/1000000000 -> 323229.13
A43: =Dados!$X$6 -> Fábrica de Massas | B43: =SUMIFS(Dados!$E$2:$E$1841,Dados!$A$2:$A$1841,$B$1,Dados!$B$2:$B$1841,"<="&$B$4,Dados!$C$2:$C$1841,$B$7,Dados!$D$2:$D$1841,A43) -> 140328.66 | C43: =IF($B$10,SUMIFS(Dados!$E$2:$E$1841,Dados!$A$2:$A$1841,$B$9,Dados!$B$2:$B$1841,"<="&$B$4,Dados!$C$2:$C$1841,$B$7,Dados!$D$2:$D$1841,A43),0) -> 267507.91 | D43: =B43+(1000-ROW())/1000000000 -> 140328.66
A44: =Dados!$X$7 -> Outros | B44: =SUMIFS(Dados!$E$2:$E$1841,Dados!$A$2:$A$1841,$B$1,Dados!$B$2:$B$1841,"<="&$B$4,Dados!$C$2:$C$1841,$B$7,Dados!$D$2:$D$1841,A44) -> 56900.43 | C44: =IF($B$10,SUMIFS(Dados!$E$2:$E$1841,Dados!$A$2:$A$1841,$B$9,Dados!$B$2:$B$1841,"<="&$B$4,Dados!$C$2:$C$1841,$B$7,Dados!$D$2:$D$1841,A44),0) -> 221333.04 | D44: =B44+(1000-ROW())/1000000000 -> 56900.43
A45: =Dados!$X$8 -> Pessoa Física | B45: =SUMIFS(Dados!$E$2:$E$1841,Dados!$A$2:$A$1841,$B$1,Dados!$B$2:$B$1841,"<="&$B$4,Dados!$C$2:$C$1841,$B$7,Dados!$D$2:$D$1841,A45) -> 90387.04 | C45: =IF($B$10,SUMIFS(Dados!$E$2:$E$1841,Dados!$A$2:$A$1841,$B$9,Dados!$B$2:$B$1841,"<="&$B$4,Dados!$C$2:$C$1841,$B$7,Dados!$D$2:$D$1841,A45),0) -> 69534.66 | D45: =B45+(1000-ROW())/1000000000 -> 90387.04
A46: =Dados!$X$9 -> Pastelaria | B46: =SUMIFS(Dados!$E$2:$E$1841,Dados!$A$2:$A$1841,$B$1,Dados!$B$2:$B$1841,"<="&$B$4,Dados!$C$2:$C$1841,$B$7,Dados!$D$2:$D$1841,A46) -> 58279.5 | C46: =IF($B$10,SUMIFS(Dados!$E$2:$E$1841,Dados!$A$2:$A$1841,$B$9,Dados!$B$2:$B$1841,"<="&$B$4,Dados!$C$2:$C$1841,$B$7,Dados!$D$2:$D$1841,A46),0) -> 73387.07 | D46: =B46+(1000-ROW())/1000000000 -> 58279.5
A47: =Dados!$X$10 -> Esfiharia | B47: =SUMIFS(Dados!$E$2:$E$1841,Dados!$A$2:$A$1841,$B$1,Dados!$B$2:$B$1841,"<="&$B$4,Dados!$C$2:$C$1841,$B$7,Dados!$D$2:$D$1841,A47) -> 81555.69 | C47: =IF($B$10,SUMIFS(Dados!$E$2:$E$1841,Dados!$A$2:$A$1841,$B$9,Dados!$B$2:$B$1841,"<="&$B$4,Dados!$C$2:$C$1841,$B$7,Dados!$D$2:$D$1841,A47),0) -> 51916.49 | D47: =B47+(1000-ROW())/1000000000 -> 81555.69
A48: =Dados!$X$11 -> Lanchonete / Cafeteria | B48: =SUMIFS(Dados!$E$2:$E$1841,Dados!$A$2:$A$1841,$B$1,Dados!$B$2:$B$1841,"<="&$B$4,Dados!$C$2:$C$1841,$B$7,Dados!$D$2:$D$1841,A48) -> 83644.1 | C48: =IF($B$10,SUMIFS(Dados!$E$2:$E$1841,Dados!$A$2:$A$1841,$B$9,Dados!$B$2:$B$1841,"<="&$B$4,Dados!$C$2:$C$1841,$B$7,Dados!$D$2:$D$1841,A48),0) -> 37971.63 | D48: =B48+(1000-ROW())/1000000000 -> 83644.1
...
